2016-05-27 07:48:37 [32440] [INFO] Starting gunicorn 19.1.0
2016-05-27 07:48:37 [32440] [INFO] Listening at: http://127.0.0.1:8000 (32440)
2016-05-27 07:48:37 [32440] [INFO] Using worker: egg:meinheld#gunicorn_worker
2016-05-27 07:48:37 [32452] [INFO] Booting worker with pid: 32452
2016-05-27 07:48:37 [32455] [INFO] Booting worker with pid: 32455
2016-05-27 07:48:37 [32440] [INFO] 2 workers
2016-05-27 07:49:01 [32455] [ERROR] Exception in worker process:
Traceback (most recent call last):
  File "/home/ralbright/anaconda2/lib/python2.7/site-packages/gunicorn-19.1.0-py2.7.egg/gunicorn/arbiter.py", line 507, in spawn_worker
    worker.init_process()
  File "/home/ralbright/anaconda2/lib/python2.7/site-packages/gunicorn-19.1.0-py2.7.egg/gunicorn/workers/base.py", line 120, in init_process
    self.run()
  File "/home/ralbright/anaconda2/lib/python2.7/site-packages/meinheld/gmeinheld.py", line 44, in run
    server.run(self.wsgi)
KeyboardInterrupt
Traceback (most recent call last):
  File "/home/ralbright/anaconda2/lib/python2.7/site-packages/gunicorn-19.1.0-py2.7.egg/gunicorn/arbiter.py", line 507, in spawn_worker
    worker.init_process()
  File "/home/ralbright/anaconda2/lib/python2.7/site-packages/gunicorn-19.1.0-py2.7.egg/gunicorn/workers/base.py", line 120, in init_process
    self.run()
  File "/home/ralbright/anaconda2/lib/python2.7/site-packages/meinheld/gmeinheld.py", line 44, in run
    server.run(self.wsgi)
KeyboardInterrupt
2016-05-27 07:49:01 [32452] [ERROR] Exception in worker process:
Traceback (most recent call last):
  File "/home/ralbright/anaconda2/lib/python2.7/site-packages/gunicorn-19.1.0-py2.7.egg/gunicorn/arbiter.py", line 507, in spawn_worker
    worker.init_process()
  File "/home/ralbright/anaconda2/lib/python2.7/site-packages/gunicorn-19.1.0-py2.7.egg/gunicorn/workers/base.py", line 120, in init_process
    self.run()
  File "/home/ralbright/anaconda2/lib/python2.7/site-packages/meinheld/gmeinheld.py", line 44, in run
    server.run(self.wsgi)
KeyboardInterrupt
Traceback (most recent call last):
  File "/home/ralbright/anaconda2/lib/python2.7/site-packages/gunicorn-19.1.0-py2.7.egg/gunicorn/arbiter.py", line 507, in spawn_worker
    worker.init_process()
  File "/home/ralbright/anaconda2/lib/python2.7/site-packages/gunicorn-19.1.0-py2.7.egg/gunicorn/workers/base.py", line 120, in init_process
    self.run()
  File "/home/ralbright/anaconda2/lib/python2.7/site-packages/meinheld/gmeinheld.py", line 44, in run
    server.run(self.wsgi)
KeyboardInterrupt
2016-05-27 07:49:01 [32455] [INFO] Worker exiting (pid: 32455)
2016-05-27 07:49:01 [32452] [INFO] Worker exiting (pid: 32452)
2016-05-27 07:49:01 [32440] [INFO] 2 workers
2016-05-27 07:49:01 [32440] [INFO] Handling signal: int
2016-05-27 07:49:01 [32440] [INFO] Shutting down: Master
2016-05-27 08:35:59 [2018] [INFO] Starting gunicorn 19.1.0
2016-05-27 08:35:59 [2018] [INFO] Listening at: http://127.0.0.1:8000 (2018)
2016-05-27 08:35:59 [2018] [INFO] Using worker: egg:meinheld#gunicorn_worker
2016-05-27 08:35:59 [2023] [INFO] Booting worker with pid: 2023
2016-05-27 08:35:59 [2024] [INFO] Booting worker with pid: 2024
2016-05-27 08:35:59 [2018] [INFO] 2 workers
2016-05-27 08:36:29 [2018] [INFO] 2 workers
2016-05-27 08:36:59 [2018] [INFO] 2 workers
2016-05-27 08:37:14 [2024] [ERROR] Exception in worker process:
Traceback (most recent call last):
  File "/home/ralbright/anaconda2/lib/python2.7/site-packages/gunicorn-19.1.0-py2.7.egg/gunicorn/arbiter.py", line 507, in spawn_worker
    worker.init_process()
  File "/home/ralbright/anaconda2/lib/python2.7/site-packages/gunicorn-19.1.0-py2.7.egg/gunicorn/workers/base.py", line 120, in init_process
    self.run()
  File "/home/ralbright/anaconda2/lib/python2.7/site-packages/meinheld/gmeinheld.py", line 44, in run
    server.run(self.wsgi)
KeyboardInterrupt
Traceback (most recent call last):
  File "/home/ralbright/anaconda2/lib/python2.7/site-packages/gunicorn-19.1.0-py2.7.egg/gunicorn/arbiter.py", line 507, in spawn_worker
    worker.init_process()
  File "/home/ralbright/anaconda2/lib/python2.7/site-packages/gunicorn-19.1.0-py2.7.egg/gunicorn/workers/base.py", line 120, in init_process
    self.run()
  File "/home/ralbright/anaconda2/lib/python2.7/site-packages/meinheld/gmeinheld.py", line 44, in run
    server.run(self.wsgi)
KeyboardInterrupt
2016-05-27 08:37:14 [2023] [ERROR] Exception in worker process:
Traceback (most recent call last):
  File "/home/ralbright/anaconda2/lib/python2.7/site-packages/gunicorn-19.1.0-py2.7.egg/gunicorn/arbiter.py", line 507, in spawn_worker
    worker.init_process()
  File "/home/ralbright/anaconda2/lib/python2.7/site-packages/gunicorn-19.1.0-py2.7.egg/gunicorn/workers/base.py", line 120, in init_process
    self.run()
  File "/home/ralbright/anaconda2/lib/python2.7/site-packages/meinheld/gmeinheld.py", line 44, in run
    server.run(self.wsgi)
KeyboardInterrupt
Traceback (most recent call last):
  File "/home/ralbright/anaconda2/lib/python2.7/site-packages/gunicorn-19.1.0-py2.7.egg/gunicorn/arbiter.py", line 507, in spawn_worker
    worker.init_process()
  File "/home/ralbright/anaconda2/lib/python2.7/site-packages/gunicorn-19.1.0-py2.7.egg/gunicorn/workers/base.py", line 120, in init_process
    self.run()
  File "/home/ralbright/anaconda2/lib/python2.7/site-packages/meinheld/gmeinheld.py", line 44, in run
    server.run(self.wsgi)
KeyboardInterrupt
2016-05-27 08:37:14 [2024] [INFO] Worker exiting (pid: 2024)
2016-05-27 08:37:14 [2023] [INFO] Worker exiting (pid: 2023)
2016-05-27 08:37:14 [2018] [INFO] 2 workers
2016-05-27 08:37:14 [2018] [INFO] Handling signal: int
2016-05-27 08:37:14 [2018] [INFO] Shutting down: Master
2016-05-27 08:38:47 [2158] [INFO] Starting gunicorn 19.1.0
2016-05-27 08:38:47 [2158] [INFO] Listening at: http://127.0.0.1:8000 (2158)
2016-05-27 08:38:47 [2158] [INFO] Using worker: egg:meinheld#gunicorn_worker
2016-05-27 08:38:47 [2163] [INFO] Booting worker with pid: 2163
2016-05-27 08:38:48 [2166] [INFO] Booting worker with pid: 2166
2016-05-27 08:38:48 [2158] [INFO] 2 workers
2016-05-27 08:39:17 [2158] [INFO] 2 workers
2016-05-27 08:39:47 [2158] [INFO] 2 workers
2016-05-27 08:40:16 [2158] [INFO] 2 workers
2016-05-27 08:40:45 [2158] [INFO] 2 workers
2016-05-27 08:41:14 [2158] [INFO] 2 workers
2016-05-27 08:41:43 [2158] [INFO] 2 workers
2016-05-27 08:42:12 [2158] [INFO] 2 workers
2016-05-27 08:42:41 [2158] [INFO] 2 workers
2016-05-27 08:43:10 [2158] [INFO] 2 workers
2016-05-27 08:43:39 [2158] [INFO] 2 workers
2016-05-27 08:44:09 [2158] [INFO] 2 workers
2016-05-27 08:44:38 [2158] [INFO] 2 workers
2016-05-27 08:45:07 [2158] [INFO] 2 workers
2016-05-27 08:45:36 [2158] [INFO] 2 workers
2016-05-27 08:46:05 [2158] [INFO] 2 workers
2016-05-27 08:46:34 [2158] [INFO] 2 workers
2016-05-27 08:46:59 [2158] [INFO] 2 workers
2016-05-27 08:46:59 [2158] [INFO] Handling signal: int
2016-05-27 08:46:59 [2166] [ERROR] Exception in worker process:
Traceback (most recent call last):
  File "/home/ralbright/anaconda2/lib/python2.7/site-packages/gunicorn-19.1.0-py2.7.egg/gunicorn/arbiter.py", line 507, in spawn_worker
    worker.init_process()
  File "/home/ralbright/anaconda2/lib/python2.7/site-packages/gunicorn-19.1.0-py2.7.egg/gunicorn/workers/base.py", line 120, in init_process
    self.run()
  File "/home/ralbright/anaconda2/lib/python2.7/site-packages/meinheld/gmeinheld.py", line 44, in run
    server.run(self.wsgi)
KeyboardInterrupt
Traceback (most recent call last):
  File "/home/ralbright/anaconda2/lib/python2.7/site-packages/gunicorn-19.1.0-py2.7.egg/gunicorn/arbiter.py", line 507, in spawn_worker
    worker.init_process()
  File "/home/ralbright/anaconda2/lib/python2.7/site-packages/gunicorn-19.1.0-py2.7.egg/gunicorn/workers/base.py", line 120, in init_process
    self.run()
  File "/home/ralbright/anaconda2/lib/python2.7/site-packages/meinheld/gmeinheld.py", line 44, in run
    server.run(self.wsgi)
KeyboardInterrupt
2016-05-27 08:46:59 [2166] [INFO] Worker exiting (pid: 2166)
2016-05-27 08:46:59 [2163] [ERROR] Exception in worker process:
Traceback (most recent call last):
  File "/home/ralbright/anaconda2/lib/python2.7/site-packages/gunicorn-19.1.0-py2.7.egg/gunicorn/arbiter.py", line 507, in spawn_worker
    worker.init_process()
  File "/home/ralbright/anaconda2/lib/python2.7/site-packages/gunicorn-19.1.0-py2.7.egg/gunicorn/workers/base.py", line 120, in init_process
    self.run()
  File "/home/ralbright/anaconda2/lib/python2.7/site-packages/meinheld/gmeinheld.py", line 44, in run
    server.run(self.wsgi)
KeyboardInterrupt
Traceback (most recent call last):
  File "/home/ralbright/anaconda2/lib/python2.7/site-packages/gunicorn-19.1.0-py2.7.egg/gunicorn/arbiter.py", line 507, in spawn_worker
    worker.init_process()
  File "/home/ralbright/anaconda2/lib/python2.7/site-packages/gunicorn-19.1.0-py2.7.egg/gunicorn/workers/base.py", line 120, in init_process
    self.run()
  File "/home/ralbright/anaconda2/lib/python2.7/site-packages/meinheld/gmeinheld.py", line 44, in run
    server.run(self.wsgi)
KeyboardInterrupt
2016-05-27 08:46:59 [2163] [INFO] Worker exiting (pid: 2163)
2016-05-27 08:46:59 [2158] [INFO] Shutting down: Master
2016-05-27 08:47:08 [2434] [INFO] Starting gunicorn 19.1.0
2016-05-27 08:47:08 [2434] [INFO] Listening at: http://127.0.0.1:8000 (2434)
2016-05-27 08:47:08 [2434] [INFO] Using worker: egg:meinheld#gunicorn_worker
2016-05-27 08:47:08 [2441] [INFO] Booting worker with pid: 2441
2016-05-27 08:47:08 [2441] [ERROR] Exception in worker process:
Traceback (most recent call last):
  File "/home/ralbright/anaconda2/lib/python2.7/site-packages/gunicorn-19.1.0-py2.7.egg/gunicorn/arbiter.py", line 507, in spawn_worker
    worker.init_process()
  File "/home/ralbright/anaconda2/lib/python2.7/site-packages/gunicorn-19.1.0-py2.7.egg/gunicorn/workers/base.py", line 114, in init_process
    self.wsgi = self.app.wsgi()
  File "/home/ralbright/anaconda2/lib/python2.7/site-packages/gunicorn-19.1.0-py2.7.egg/gunicorn/app/base.py", line 66, in wsgi
    self.callable = self.load()
  File "/home/ralbright/anaconda2/lib/python2.7/site-packages/gunicorn-19.1.0-py2.7.egg/gunicorn/app/wsgiapp.py", line 65, in load
    return self.load_wsgiapp()
  File "/home/ralbright/anaconda2/lib/python2.7/site-packages/gunicorn-19.1.0-py2.7.egg/gunicorn/app/wsgiapp.py", line 52, in load_wsgiapp
    return util.import_app(self.app_uri)
  File "/home/ralbright/anaconda2/lib/python2.7/site-packages/gunicorn-19.1.0-py2.7.egg/gunicorn/util.py", line 356, in import_app
    __import__(module)
ImportError: No module named run
Traceback (most recent call last):
  File "/home/ralbright/anaconda2/lib/python2.7/site-packages/gunicorn-19.1.0-py2.7.egg/gunicorn/arbiter.py", line 507, in spawn_worker
    worker.init_process()
  File "/home/ralbright/anaconda2/lib/python2.7/site-packages/gunicorn-19.1.0-py2.7.egg/gunicorn/workers/base.py", line 114, in init_process
    self.wsgi = self.app.wsgi()
  File "/home/ralbright/anaconda2/lib/python2.7/site-packages/gunicorn-19.1.0-py2.7.egg/gunicorn/app/base.py", line 66, in wsgi
    self.callable = self.load()
  File "/home/ralbright/anaconda2/lib/python2.7/site-packages/gunicorn-19.1.0-py2.7.egg/gunicorn/app/wsgiapp.py", line 65, in load
    return self.load_wsgiapp()
  File "/home/ralbright/anaconda2/lib/python2.7/site-packages/gunicorn-19.1.0-py2.7.egg/gunicorn/app/wsgiapp.py", line 52, in load_wsgiapp
    return util.import_app(self.app_uri)
  File "/home/ralbright/anaconda2/lib/python2.7/site-packages/gunicorn-19.1.0-py2.7.egg/gunicorn/util.py", line 356, in import_app
    __import__(module)
ImportError: No module named run
2016-05-27 08:47:08 [2441] [INFO] Worker exiting (pid: 2441)
2016-05-27 08:47:59 [2491] [INFO] Starting gunicorn 19.1.0
2016-05-27 08:47:59 [2491] [INFO] Listening at: http://127.0.0.1:8000 (2491)
2016-05-27 08:47:59 [2491] [INFO] Using worker: egg:meinheld#gunicorn_worker
2016-05-27 08:47:59 [2496] [INFO] Booting worker with pid: 2496
2016-05-27 08:47:59 [2497] [INFO] Booting worker with pid: 2497
2016-05-27 08:47:59 [2491] [INFO] 2 workers
2016-05-27 08:48:29 [2491] [INFO] 2 workers
2016-05-27 08:48:45 [2496] [ERROR] Exception in worker process:
Traceback (most recent call last):
  File "/home/ralbright/anaconda2/lib/python2.7/site-packages/gunicorn-19.1.0-py2.7.egg/gunicorn/arbiter.py", line 507, in spawn_worker
    worker.init_process()
  File "/home/ralbright/anaconda2/lib/python2.7/site-packages/gunicorn-19.1.0-py2.7.egg/gunicorn/workers/base.py", line 120, in init_process
    self.run()
  File "/home/ralbright/anaconda2/lib/python2.7/site-packages/meinheld/gmeinheld.py", line 44, in run
    server.run(self.wsgi)
KeyboardInterrupt
Traceback (most recent call last):
  File "/home/ralbright/anaconda2/lib/python2.7/site-packages/gunicorn-19.1.0-py2.7.egg/gunicorn/arbiter.py", line 507, in spawn_worker
    worker.init_process()
  File "/home/ralbright/anaconda2/lib/python2.7/site-packages/gunicorn-19.1.0-py2.7.egg/gunicorn/workers/base.py", line 120, in init_process
    self.run()
  File "/home/ralbright/anaconda2/lib/python2.7/site-packages/meinheld/gmeinheld.py", line 44, in run
    server.run(self.wsgi)
KeyboardInterrupt
2016-05-27 08:48:45 [2497] [ERROR] Exception in worker process:
Traceback (most recent call last):
  File "/home/ralbright/anaconda2/lib/python2.7/site-packages/gunicorn-19.1.0-py2.7.egg/gunicorn/arbiter.py", line 507, in spawn_worker
    worker.init_process()
  File "/home/ralbright/anaconda2/lib/python2.7/site-packages/gunicorn-19.1.0-py2.7.egg/gunicorn/workers/base.py", line 120, in init_process
    self.run()
  File "/home/ralbright/anaconda2/lib/python2.7/site-packages/meinheld/gmeinheld.py", line 44, in run
    server.run(self.wsgi)
KeyboardInterrupt
Traceback (most recent call last):
  File "/home/ralbright/anaconda2/lib/python2.7/site-packages/gunicorn-19.1.0-py2.7.egg/gunicorn/arbiter.py", line 507, in spawn_worker
    worker.init_process()
  File "/home/ralbright/anaconda2/lib/python2.7/site-packages/gunicorn-19.1.0-py2.7.egg/gunicorn/workers/base.py", line 120, in init_process
    self.run()
  File "/home/ralbright/anaconda2/lib/python2.7/site-packages/meinheld/gmeinheld.py", line 44, in run
    server.run(self.wsgi)
KeyboardInterrupt
2016-05-27 08:48:45 [2496] [INFO] Worker exiting (pid: 2496)
2016-05-27 08:48:45 [2497] [INFO] Worker exiting (pid: 2497)
2016-05-27 08:48:45 [2491] [INFO] 2 workers
2016-05-27 08:48:45 [2491] [INFO] Handling signal: int
2016-05-27 08:48:45 [2491] [INFO] Shutting down: Master
2016-05-28 09:04:21 [2567] [INFO] Starting gunicorn 19.1.0
2016-05-28 09:04:21 [2567] [INFO] Listening at: http://127.0.0.1:8000 (2567)
2016-05-28 09:04:21 [2567] [INFO] Using worker: egg:meinheld#gunicorn_worker
2016-05-28 09:04:21 [2572] [INFO] Booting worker with pid: 2572
2016-05-28 09:04:21 [2573] [INFO] Booting worker with pid: 2573
2016-05-28 09:04:21 [2567] [INFO] 2 workers
2016-05-28 09:04:51 [2567] [INFO] 2 workers
2016-05-28 09:05:20 [2567] [INFO] 2 workers
2016-05-28 09:05:50 [2567] [INFO] 2 workers
2016-05-28 09:05:53 [2567] [INFO] 2 workers
2016-05-28 09:05:53 [2567] [INFO] Handling signal: int
2016-05-28 09:05:53 [2572] [ERROR] Exception in worker process:
Traceback (most recent call last):
  File "/home/ralbright/anaconda2/lib/python2.7/site-packages/gunicorn-19.1.0-py2.7.egg/gunicorn/arbiter.py", line 507, in spawn_worker
    worker.init_process()
  File "/home/ralbright/anaconda2/lib/python2.7/site-packages/gunicorn-19.1.0-py2.7.egg/gunicorn/workers/base.py", line 120, in init_process
    self.run()
  File "/home/ralbright/anaconda2/lib/python2.7/site-packages/meinheld/gmeinheld.py", line 44, in run
    server.run(self.wsgi)
KeyboardInterrupt
Traceback (most recent call last):
  File "/home/ralbright/anaconda2/lib/python2.7/site-packages/gunicorn-19.1.0-py2.7.egg/gunicorn/arbiter.py", line 507, in spawn_worker
    worker.init_process()
  File "/home/ralbright/anaconda2/lib/python2.7/site-packages/gunicorn-19.1.0-py2.7.egg/gunicorn/workers/base.py", line 120, in init_process
    self.run()
  File "/home/ralbright/anaconda2/lib/python2.7/site-packages/meinheld/gmeinheld.py", line 44, in run
    server.run(self.wsgi)
KeyboardInterrupt
2016-05-28 09:05:53 [2573] [ERROR] Exception in worker process:
Traceback (most recent call last):
  File "/home/ralbright/anaconda2/lib/python2.7/site-packages/gunicorn-19.1.0-py2.7.egg/gunicorn/arbiter.py", line 507, in spawn_worker
    worker.init_process()
  File "/home/ralbright/anaconda2/lib/python2.7/site-packages/gunicorn-19.1.0-py2.7.egg/gunicorn/workers/base.py", line 120, in init_process
    self.run()
  File "/home/ralbright/anaconda2/lib/python2.7/site-packages/meinheld/gmeinheld.py", line 44, in run
    server.run(self.wsgi)
KeyboardInterrupt
Traceback (most recent call last):
  File "/home/ralbright/anaconda2/lib/python2.7/site-packages/gunicorn-19.1.0-py2.7.egg/gunicorn/arbiter.py", line 507, in spawn_worker
    worker.init_process()
  File "/home/ralbright/anaconda2/lib/python2.7/site-packages/gunicorn-19.1.0-py2.7.egg/gunicorn/workers/base.py", line 120, in init_process
    self.run()
  File "/home/ralbright/anaconda2/lib/python2.7/site-packages/meinheld/gmeinheld.py", line 44, in run
    server.run(self.wsgi)
KeyboardInterrupt
2016-05-28 09:05:53 [2572] [INFO] Worker exiting (pid: 2572)
2016-05-28 09:05:53 [2573] [INFO] Worker exiting (pid: 2573)
2016-05-28 09:05:53 [2567] [INFO] Shutting down: Master
2016-06-07 19:52:12 [2873] [INFO] Starting gunicorn 19.1.0
2016-06-07 19:52:12 [2873] [INFO] Listening at: http://127.0.0.1:8000 (2873)
2016-06-07 19:52:12 [2873] [INFO] Using worker: egg:meinheld#gunicorn_worker
2016-06-07 19:52:12 [2878] [INFO] Booting worker with pid: 2878
2016-06-07 19:52:12 [2879] [INFO] Booting worker with pid: 2879
2016-06-07 19:52:12 [2873] [INFO] 2 workers
2016-06-07 19:52:12 [2878] [ERROR] Exception in worker process:
Traceback (most recent call last):
  File "/home/ralbright/anaconda2/lib/python2.7/site-packages/gunicorn-19.1.0-py2.7.egg/gunicorn/arbiter.py", line 507, in spawn_worker
    worker.init_process()
  File "/home/ralbright/anaconda2/lib/python2.7/site-packages/gunicorn-19.1.0-py2.7.egg/gunicorn/workers/base.py", line 114, in init_process
    self.wsgi = self.app.wsgi()
  File "/home/ralbright/anaconda2/lib/python2.7/site-packages/gunicorn-19.1.0-py2.7.egg/gunicorn/app/base.py", line 66, in wsgi
    self.callable = self.load()
  File "/home/ralbright/anaconda2/lib/python2.7/site-packages/gunicorn-19.1.0-py2.7.egg/gunicorn/app/wsgiapp.py", line 65, in load
    return self.load_wsgiapp()
  File "/home/ralbright/anaconda2/lib/python2.7/site-packages/gunicorn-19.1.0-py2.7.egg/gunicorn/app/wsgiapp.py", line 52, in load_wsgiapp
    return util.import_app(self.app_uri)
  File "/home/ralbright/anaconda2/lib/python2.7/site-packages/gunicorn-19.1.0-py2.7.egg/gunicorn/util.py", line 356, in import_app
    __import__(module)
  File "/home/ralbright/projects/rest-example/bin/restserver.py", line 16, in <module>
    from task import fib
ImportError: No module named task
Traceback (most recent call last):
  File "/home/ralbright/anaconda2/lib/python2.7/site-packages/gunicorn-19.1.0-py2.7.egg/gunicorn/arbiter.py", line 507, in spawn_worker
    worker.init_process()
  File "/home/ralbright/anaconda2/lib/python2.7/site-packages/gunicorn-19.1.0-py2.7.egg/gunicorn/workers/base.py", line 114, in init_process
    self.wsgi = self.app.wsgi()
  File "/home/ralbright/anaconda2/lib/python2.7/site-packages/gunicorn-19.1.0-py2.7.egg/gunicorn/app/base.py", line 66, in wsgi
    self.callable = self.load()
  File "/home/ralbright/anaconda2/lib/python2.7/site-packages/gunicorn-19.1.0-py2.7.egg/gunicorn/app/wsgiapp.py", line 65, in load
    return self.load_wsgiapp()
  File "/home/ralbright/anaconda2/lib/python2.7/site-packages/gunicorn-19.1.0-py2.7.egg/gunicorn/app/wsgiapp.py", line 52, in load_wsgiapp
    return util.import_app(self.app_uri)
  File "/home/ralbright/anaconda2/lib/python2.7/site-packages/gunicorn-19.1.0-py2.7.egg/gunicorn/util.py", line 356, in import_app
    __import__(module)
  File "/home/ralbright/projects/rest-example/bin/restserver.py", line 16, in <module>
    from task import fib
ImportError: No module named task
2016-06-07 19:52:12 [2879] [ERROR] Exception in worker process:
Traceback (most recent call last):
  File "/home/ralbright/anaconda2/lib/python2.7/site-packages/gunicorn-19.1.0-py2.7.egg/gunicorn/arbiter.py", line 507, in spawn_worker
    worker.init_process()
  File "/home/ralbright/anaconda2/lib/python2.7/site-packages/gunicorn-19.1.0-py2.7.egg/gunicorn/workers/base.py", line 114, in init_process
    self.wsgi = self.app.wsgi()
  File "/home/ralbright/anaconda2/lib/python2.7/site-packages/gunicorn-19.1.0-py2.7.egg/gunicorn/app/base.py", line 66, in wsgi
    self.callable = self.load()
  File "/home/ralbright/anaconda2/lib/python2.7/site-packages/gunicorn-19.1.0-py2.7.egg/gunicorn/app/wsgiapp.py", line 65, in load
    return self.load_wsgiapp()
  File "/home/ralbright/anaconda2/lib/python2.7/site-packages/gunicorn-19.1.0-py2.7.egg/gunicorn/app/wsgiapp.py", line 52, in load_wsgiapp
    return util.import_app(self.app_uri)
  File "/home/ralbright/anaconda2/lib/python2.7/site-packages/gunicorn-19.1.0-py2.7.egg/gunicorn/util.py", line 356, in import_app
    __import__(module)
  File "/home/ralbright/projects/rest-example/bin/restserver.py", line 16, in <module>
    from task import fib
ImportError: No module named task
Traceback (most recent call last):
  File "/home/ralbright/anaconda2/lib/python2.7/site-packages/gunicorn-19.1.0-py2.7.egg/gunicorn/arbiter.py", line 507, in spawn_worker
    worker.init_process()
  File "/home/ralbright/anaconda2/lib/python2.7/site-packages/gunicorn-19.1.0-py2.7.egg/gunicorn/workers/base.py", line 114, in init_process
    self.wsgi = self.app.wsgi()
  File "/home/ralbright/anaconda2/lib/python2.7/site-packages/gunicorn-19.1.0-py2.7.egg/gunicorn/app/base.py", line 66, in wsgi
    self.callable = self.load()
  File "/home/ralbright/anaconda2/lib/python2.7/site-packages/gunicorn-19.1.0-py2.7.egg/gunicorn/app/wsgiapp.py", line 65, in load
    return self.load_wsgiapp()
  File "/home/ralbright/anaconda2/lib/python2.7/site-packages/gunicorn-19.1.0-py2.7.egg/gunicorn/app/wsgiapp.py", line 52, in load_wsgiapp
    return util.import_app(self.app_uri)
  File "/home/ralbright/anaconda2/lib/python2.7/site-packages/gunicorn-19.1.0-py2.7.egg/gunicorn/util.py", line 356, in import_app
    __import__(module)
  File "/home/ralbright/projects/rest-example/bin/restserver.py", line 16, in <module>
    from task import fib
ImportError: No module named task
2016-06-07 19:52:12 [2878] [INFO] Worker exiting (pid: 2878)
2016-06-07 19:52:12 [2879] [INFO] Worker exiting (pid: 2879)
2016-06-07 19:52:43 [2873] [INFO] Shutting down: Master
2016-06-07 19:52:43 [2873] [INFO] Reason: Worker failed to boot.
2016-06-07 19:56:35 [3120] [INFO] Starting gunicorn 19.1.0
2016-06-07 19:56:35 [3120] [INFO] Listening at: http://127.0.0.1:8000 (3120)
2016-06-07 19:56:35 [3120] [INFO] Using worker: egg:meinheld#gunicorn_worker
2016-06-07 19:56:35 [3125] [INFO] Booting worker with pid: 3125
2016-06-07 19:56:35 [3126] [INFO] Booting worker with pid: 3126
2016-06-07 19:56:35 [3120] [INFO] 2 workers
2016-06-07 19:56:58 [3126] [ERROR] Traceback (most recent call last):
  File "/home/ralbright/anaconda2/lib/python2.7/site-packages/falcon/api.py", line 182, in __call__
    responder(req, resp, **params)
  File "/home/ralbright/projects/rest-example/restserver.py", line 26, in on_get
    jsonFibArr = json.dumps(fibArr)
  File "/home/ralbright/anaconda2/lib/python2.7/json/__init__.py", line 244, in dumps
    return _default_encoder.encode(obj)
  File "/home/ralbright/anaconda2/lib/python2.7/json/encoder.py", line 207, in encode
    chunks = self.iterencode(o, _one_shot=True)
  File "/home/ralbright/anaconda2/lib/python2.7/json/encoder.py", line 270, in iterencode
    return _iterencode(o, 0)
  File "/home/ralbright/anaconda2/lib/python2.7/json/encoder.py", line 184, in default
    raise TypeError(repr(o) + " is not JSON serializable")
TypeError: <AsyncResult: 5adc2494-c97c-46ca-8f0f-e318d0502b3b> is not JSON serializable

2016-06-07 19:57:03 [3126] [ERROR] Traceback (most recent call last):
  File "/home/ralbright/anaconda2/lib/python2.7/site-packages/falcon/api.py", line 182, in __call__
    responder(req, resp, **params)
  File "/home/ralbright/projects/rest-example/restserver.py", line 26, in on_get
    jsonFibArr = json.dumps(fibArr)
  File "/home/ralbright/anaconda2/lib/python2.7/json/__init__.py", line 244, in dumps
    return _default_encoder.encode(obj)
  File "/home/ralbright/anaconda2/lib/python2.7/json/encoder.py", line 207, in encode
    chunks = self.iterencode(o, _one_shot=True)
  File "/home/ralbright/anaconda2/lib/python2.7/json/encoder.py", line 270, in iterencode
    return _iterencode(o, 0)
  File "/home/ralbright/anaconda2/lib/python2.7/json/encoder.py", line 184, in default
    raise TypeError(repr(o) + " is not JSON serializable")
TypeError: <AsyncResult: 6ef61ebb-b1e0-47fd-a0f4-5e4b7f15e86f> is not JSON serializable

2016-06-07 19:57:03 [3126] [ERROR] Traceback (most recent call last):
  File "/home/ralbright/anaconda2/lib/python2.7/site-packages/falcon/api.py", line 182, in __call__
    responder(req, resp, **params)
  File "/home/ralbright/projects/rest-example/restserver.py", line 26, in on_get
    jsonFibArr = json.dumps(fibArr)
  File "/home/ralbright/anaconda2/lib/python2.7/json/__init__.py", line 244, in dumps
    return _default_encoder.encode(obj)
  File "/home/ralbright/anaconda2/lib/python2.7/json/encoder.py", line 207, in encode
    chunks = self.iterencode(o, _one_shot=True)
  File "/home/ralbright/anaconda2/lib/python2.7/json/encoder.py", line 270, in iterencode
    return _iterencode(o, 0)
  File "/home/ralbright/anaconda2/lib/python2.7/json/encoder.py", line 184, in default
    raise TypeError(repr(o) + " is not JSON serializable")
TypeError: <AsyncResult: 656a408c-733f-4f46-894a-f09904e67814> is not JSON serializable

2016-06-07 19:57:05 [3120] [INFO] 2 workers
2016-06-07 19:57:09 [3120] [INFO] 2 workers
2016-06-07 19:57:09 [3120] [INFO] Handling signal: int
2016-06-07 19:57:09 [3126] [ERROR] Exception in worker process:
Traceback (most recent call last):
  File "/home/ralbright/anaconda2/lib/python2.7/site-packages/gunicorn-19.1.0-py2.7.egg/gunicorn/arbiter.py", line 507, in spawn_worker
    worker.init_process()
  File "/home/ralbright/anaconda2/lib/python2.7/site-packages/gunicorn-19.1.0-py2.7.egg/gunicorn/workers/base.py", line 120, in init_process
    self.run()
  File "/home/ralbright/anaconda2/lib/python2.7/site-packages/meinheld/gmeinheld.py", line 44, in run
    server.run(self.wsgi)
KeyboardInterrupt
Traceback (most recent call last):
  File "/home/ralbright/anaconda2/lib/python2.7/site-packages/gunicorn-19.1.0-py2.7.egg/gunicorn/arbiter.py", line 507, in spawn_worker
    worker.init_process()
  File "/home/ralbright/anaconda2/lib/python2.7/site-packages/gunicorn-19.1.0-py2.7.egg/gunicorn/workers/base.py", line 120, in init_process
    self.run()
  File "/home/ralbright/anaconda2/lib/python2.7/site-packages/meinheld/gmeinheld.py", line 44, in run
    server.run(self.wsgi)
KeyboardInterrupt
2016-06-07 19:57:09 [3125] [ERROR] Exception in worker process:
Traceback (most recent call last):
  File "/home/ralbright/anaconda2/lib/python2.7/site-packages/gunicorn-19.1.0-py2.7.egg/gunicorn/arbiter.py", line 507, in spawn_worker
    worker.init_process()
  File "/home/ralbright/anaconda2/lib/python2.7/site-packages/gunicorn-19.1.0-py2.7.egg/gunicorn/workers/base.py", line 120, in init_process
    self.run()
  File "/home/ralbright/anaconda2/lib/python2.7/site-packages/meinheld/gmeinheld.py", line 44, in run
    server.run(self.wsgi)
KeyboardInterrupt
Traceback (most recent call last):
  File "/home/ralbright/anaconda2/lib/python2.7/site-packages/gunicorn-19.1.0-py2.7.egg/gunicorn/arbiter.py", line 507, in spawn_worker
    worker.init_process()
  File "/home/ralbright/anaconda2/lib/python2.7/site-packages/gunicorn-19.1.0-py2.7.egg/gunicorn/workers/base.py", line 120, in init_process
    self.run()
  File "/home/ralbright/anaconda2/lib/python2.7/site-packages/meinheld/gmeinheld.py", line 44, in run
    server.run(self.wsgi)
KeyboardInterrupt
2016-06-07 19:57:09 [3125] [INFO] Worker exiting (pid: 3125)
2016-06-07 19:57:09 [3126] [INFO] Worker exiting (pid: 3126)
2016-06-07 19:57:09 [3120] [INFO] Shutting down: Master
2016-06-07 19:57:52 [3507] [INFO] Starting gunicorn 19.1.0
2016-06-07 19:57:52 [3507] [INFO] Listening at: http://127.0.0.1:8000 (3507)
2016-06-07 19:57:52 [3507] [INFO] Using worker: egg:meinheld#gunicorn_worker
2016-06-07 19:57:52 [3512] [INFO] Booting worker with pid: 3512
2016-06-07 19:57:52 [3515] [INFO] Booting worker with pid: 3515
2016-06-07 19:57:52 [3507] [INFO] 2 workers
2016-06-07 19:57:57 [3515] [ERROR] Traceback (most recent call last):
  File "/home/ralbright/anaconda2/lib/python2.7/site-packages/falcon/api.py", line 182, in __call__
    responder(req, resp, **params)
  File "/home/ralbright/projects/rest-example/restserver.py", line 26, in on_get
    jsonFibArr = json.dumps(fibArr)
  File "/home/ralbright/anaconda2/lib/python2.7/json/__init__.py", line 244, in dumps
    return _default_encoder.encode(obj)
  File "/home/ralbright/anaconda2/lib/python2.7/json/encoder.py", line 207, in encode
    chunks = self.iterencode(o, _one_shot=True)
  File "/home/ralbright/anaconda2/lib/python2.7/json/encoder.py", line 270, in iterencode
    return _iterencode(o, 0)
  File "/home/ralbright/anaconda2/lib/python2.7/json/encoder.py", line 184, in default
    raise TypeError(repr(o) + " is not JSON serializable")
TypeError: <AsyncResult: de45d569-16e9-459e-a1b9-6650278766ba> is not JSON serializable

2016-06-07 19:58:07 [3507] [INFO] 2 workers
2016-06-07 19:58:07 [3507] [INFO] Handling signal: winch
2016-06-07 19:58:07 [3507] [INFO] 2 workers
2016-06-07 19:58:07 [3507] [INFO] 2 workers
2016-06-07 19:58:07 [3507] [INFO] Handling signal: winch
2016-06-07 19:58:07 [3507] [INFO] 2 workers
2016-06-07 19:58:37 [3507] [INFO] 2 workers
2016-06-07 19:59:06 [3507] [INFO] 2 workers
2016-06-07 19:59:35 [3507] [INFO] 2 workers
2016-06-07 20:00:04 [3507] [INFO] 2 workers
2016-06-07 20:00:33 [3507] [INFO] 2 workers
2016-06-07 20:01:02 [3507] [INFO] 2 workers
2016-06-07 20:01:31 [3507] [INFO] 2 workers
2016-06-07 20:02:00 [3507] [INFO] 2 workers
2016-06-07 20:02:29 [3507] [INFO] 2 workers
2016-06-07 20:02:58 [3507] [INFO] 2 workers
2016-06-07 20:03:27 [3507] [INFO] 2 workers
2016-06-07 20:03:56 [3507] [INFO] 2 workers
2016-06-07 20:04:25 [3507] [INFO] 2 workers
2016-06-07 20:04:46 [3512] [ERROR] Exception in worker process:
Traceback (most recent call last):
  File "/home/ralbright/anaconda2/lib/python2.7/site-packages/gunicorn-19.1.0-py2.7.egg/gunicorn/arbiter.py", line 507, in spawn_worker
    worker.init_process()
  File "/home/ralbright/anaconda2/lib/python2.7/site-packages/gunicorn-19.1.0-py2.7.egg/gunicorn/workers/base.py", line 120, in init_process
    self.run()
  File "/home/ralbright/anaconda2/lib/python2.7/site-packages/meinheld/gmeinheld.py", line 44, in run
    server.run(self.wsgi)
KeyboardInterrupt
Traceback (most recent call last):
  File "/home/ralbright/anaconda2/lib/python2.7/site-packages/gunicorn-19.1.0-py2.7.egg/gunicorn/arbiter.py", line 507, in spawn_worker
    worker.init_process()
  File "/home/ralbright/anaconda2/lib/python2.7/site-packages/gunicorn-19.1.0-py2.7.egg/gunicorn/workers/base.py", line 120, in init_process
    self.run()
  File "/home/ralbright/anaconda2/lib/python2.7/site-packages/meinheld/gmeinheld.py", line 44, in run
    server.run(self.wsgi)
KeyboardInterrupt
2016-06-07 20:04:46 [3507] [INFO] 2 workers
2016-06-07 20:04:46 [3507] [INFO] Handling signal: int
2016-06-07 20:04:46 [3515] [ERROR] Exception in worker process:
Traceback (most recent call last):
  File "/home/ralbright/anaconda2/lib/python2.7/site-packages/gunicorn-19.1.0-py2.7.egg/gunicorn/arbiter.py", line 507, in spawn_worker
    worker.init_process()
  File "/home/ralbright/anaconda2/lib/python2.7/site-packages/gunicorn-19.1.0-py2.7.egg/gunicorn/workers/base.py", line 120, in init_process
    self.run()
  File "/home/ralbright/anaconda2/lib/python2.7/site-packages/meinheld/gmeinheld.py", line 44, in run
    server.run(self.wsgi)
KeyboardInterrupt
Traceback (most recent call last):
  File "/home/ralbright/anaconda2/lib/python2.7/site-packages/gunicorn-19.1.0-py2.7.egg/gunicorn/arbiter.py", line 507, in spawn_worker
    worker.init_process()
  File "/home/ralbright/anaconda2/lib/python2.7/site-packages/gunicorn-19.1.0-py2.7.egg/gunicorn/workers/base.py", line 120, in init_process
    self.run()
  File "/home/ralbright/anaconda2/lib/python2.7/site-packages/meinheld/gmeinheld.py", line 44, in run
    server.run(self.wsgi)
KeyboardInterrupt
2016-06-07 20:04:46 [3512] [INFO] Worker exiting (pid: 3512)
2016-06-07 20:04:46 [3515] [INFO] Worker exiting (pid: 3515)
2016-06-07 20:04:46 [3507] [INFO] Shutting down: Master
2016-06-07 20:09:52 [3835] [INFO] Starting gunicorn 19.1.0
2016-06-07 20:09:52 [3835] [INFO] Listening at: http://127.0.0.1:8000 (3835)
2016-06-07 20:09:52 [3835] [INFO] Using worker: egg:meinheld#gunicorn_worker
2016-06-07 20:09:52 [3840] [INFO] Booting worker with pid: 3840
2016-06-07 20:09:52 [3843] [INFO] Booting worker with pid: 3843
2016-06-07 20:09:52 [3835] [INFO] 2 workers
2016-06-07 20:10:05 [3835] [INFO] 2 workers
2016-06-07 20:10:05 [3835] [INFO] Handling signal: int
2016-06-07 20:10:05 [3840] [ERROR] Exception in worker process:
Traceback (most recent call last):
  File "/home/ralbright/anaconda2/lib/python2.7/site-packages/gunicorn-19.1.0-py2.7.egg/gunicorn/arbiter.py", line 507, in spawn_worker
    worker.init_process()
  File "/home/ralbright/anaconda2/lib/python2.7/site-packages/gunicorn-19.1.0-py2.7.egg/gunicorn/workers/base.py", line 120, in init_process
    self.run()
  File "/home/ralbright/anaconda2/lib/python2.7/site-packages/meinheld/gmeinheld.py", line 44, in run
    server.run(self.wsgi)
KeyboardInterrupt
Traceback (most recent call last):
  File "/home/ralbright/anaconda2/lib/python2.7/site-packages/gunicorn-19.1.0-py2.7.egg/gunicorn/arbiter.py", line 507, in spawn_worker
    worker.init_process()
  File "/home/ralbright/anaconda2/lib/python2.7/site-packages/gunicorn-19.1.0-py2.7.egg/gunicorn/workers/base.py", line 120, in init_process
    self.run()
  File "/home/ralbright/anaconda2/lib/python2.7/site-packages/meinheld/gmeinheld.py", line 44, in run
    server.run(self.wsgi)
KeyboardInterrupt
2016-06-07 20:10:05 [3840] [INFO] Worker exiting (pid: 3840)
2016-06-07 20:10:05 [3843] [ERROR] Exception in worker process:
Traceback (most recent call last):
  File "/home/ralbright/anaconda2/lib/python2.7/site-packages/gunicorn-19.1.0-py2.7.egg/gunicorn/arbiter.py", line 507, in spawn_worker
    worker.init_process()
  File "/home/ralbright/anaconda2/lib/python2.7/site-packages/gunicorn-19.1.0-py2.7.egg/gunicorn/workers/base.py", line 120, in init_process
    self.run()
  File "/home/ralbright/anaconda2/lib/python2.7/site-packages/meinheld/gmeinheld.py", line 44, in run
    server.run(self.wsgi)
KeyboardInterrupt
Traceback (most recent call last):
  File "/home/ralbright/anaconda2/lib/python2.7/site-packages/gunicorn-19.1.0-py2.7.egg/gunicorn/arbiter.py", line 507, in spawn_worker
    worker.init_process()
  File "/home/ralbright/anaconda2/lib/python2.7/site-packages/gunicorn-19.1.0-py2.7.egg/gunicorn/workers/base.py", line 120, in init_process
    self.run()
  File "/home/ralbright/anaconda2/lib/python2.7/site-packages/meinheld/gmeinheld.py", line 44, in run
    server.run(self.wsgi)
KeyboardInterrupt
2016-06-07 20:10:05 [3843] [INFO] Worker exiting (pid: 3843)
2016-06-07 20:10:05 [3835] [INFO] Shutting down: Master
2016-06-07 20:11:07 [3961] [INFO] Starting gunicorn 19.1.0
2016-06-07 20:11:07 [3961] [INFO] Listening at: http://127.0.0.1:8000 (3961)
2016-06-07 20:11:07 [3961] [INFO] Using worker: egg:meinheld#gunicorn_worker
2016-06-07 20:11:07 [3966] [INFO] Booting worker with pid: 3966
2016-06-07 20:11:07 [3969] [INFO] Booting worker with pid: 3969
2016-06-07 20:11:07 [3961] [INFO] 2 workers
2016-06-07 20:11:13 [3969] [ERROR] Traceback (most recent call last):
  File "/home/ralbright/anaconda2/lib/python2.7/site-packages/falcon/api.py", line 182, in __call__
    responder(req, resp, **params)
  File "/home/ralbright/projects/rest-example/restserver.py", line 24, in on_get
    async = fib.apply_async(n)
  File "/home/ralbright/anaconda2/lib/python2.7/site-packages/celery/app/task.py", line 565, in apply_async
    **dict(self._get_exec_options(), **options)
  File "/home/ralbright/anaconda2/lib/python2.7/site-packages/celery/app/base.py", line 354, in send_task
    reply_to=reply_to or self.oid, **options
  File "/home/ralbright/anaconda2/lib/python2.7/site-packages/celery/app/amqp.py", line 252, in publish_task
    raise ValueError('task args must be a list or tuple')
ValueError: task args must be a list or tuple

2016-06-07 20:11:16 [3966] [ERROR] Traceback (most recent call last):
  File "/home/ralbright/anaconda2/lib/python2.7/site-packages/falcon/api.py", line 182, in __call__
    responder(req, resp, **params)
  File "/home/ralbright/projects/rest-example/restserver.py", line 24, in on_get
    async = fib.apply_async(n)
  File "/home/ralbright/anaconda2/lib/python2.7/site-packages/celery/app/task.py", line 565, in apply_async
    **dict(self._get_exec_options(), **options)
  File "/home/ralbright/anaconda2/lib/python2.7/site-packages/celery/app/base.py", line 354, in send_task
    reply_to=reply_to or self.oid, **options
  File "/home/ralbright/anaconda2/lib/python2.7/site-packages/celery/app/amqp.py", line 252, in publish_task
    raise ValueError('task args must be a list or tuple')
ValueError: task args must be a list or tuple

2016-06-07 20:11:37 [3961] [INFO] 2 workers
2016-06-07 20:12:07 [3961] [INFO] 2 workers
2016-06-07 20:12:10 [3969] [ERROR] Exception in worker process:
Traceback (most recent call last):
  File "/home/ralbright/anaconda2/lib/python2.7/site-packages/gunicorn-19.1.0-py2.7.egg/gunicorn/arbiter.py", line 507, in spawn_worker
    worker.init_process()
  File "/home/ralbright/anaconda2/lib/python2.7/site-packages/gunicorn-19.1.0-py2.7.egg/gunicorn/workers/base.py", line 120, in init_process
    self.run()
  File "/home/ralbright/anaconda2/lib/python2.7/site-packages/meinheld/gmeinheld.py", line 44, in run
    server.run(self.wsgi)
KeyboardInterrupt
Traceback (most recent call last):
  File "/home/ralbright/anaconda2/lib/python2.7/site-packages/gunicorn-19.1.0-py2.7.egg/gunicorn/arbiter.py", line 507, in spawn_worker
    worker.init_process()
  File "/home/ralbright/anaconda2/lib/python2.7/site-packages/gunicorn-19.1.0-py2.7.egg/gunicorn/workers/base.py", line 120, in init_process
    self.run()
  File "/home/ralbright/anaconda2/lib/python2.7/site-packages/meinheld/gmeinheld.py", line 44, in run
    server.run(self.wsgi)
KeyboardInterrupt
2016-06-07 20:12:10 [3966] [ERROR] Exception in worker process:
Traceback (most recent call last):
  File "/home/ralbright/anaconda2/lib/python2.7/site-packages/gunicorn-19.1.0-py2.7.egg/gunicorn/arbiter.py", line 507, in spawn_worker
    worker.init_process()
  File "/home/ralbright/anaconda2/lib/python2.7/site-packages/gunicorn-19.1.0-py2.7.egg/gunicorn/workers/base.py", line 120, in init_process
    self.run()
  File "/home/ralbright/anaconda2/lib/python2.7/site-packages/meinheld/gmeinheld.py", line 44, in run
    server.run(self.wsgi)
KeyboardInterrupt
Traceback (most recent call last):
  File "/home/ralbright/anaconda2/lib/python2.7/site-packages/gunicorn-19.1.0-py2.7.egg/gunicorn/arbiter.py", line 507, in spawn_worker
    worker.init_process()
  File "/home/ralbright/anaconda2/lib/python2.7/site-packages/gunicorn-19.1.0-py2.7.egg/gunicorn/workers/base.py", line 120, in init_process
    self.run()
  File "/home/ralbright/anaconda2/lib/python2.7/site-packages/meinheld/gmeinheld.py", line 44, in run
    server.run(self.wsgi)
KeyboardInterrupt
2016-06-07 20:12:10 [3969] [INFO] Worker exiting (pid: 3969)
2016-06-07 20:12:10 [3966] [INFO] Worker exiting (pid: 3966)
2016-06-07 20:12:10 [3961] [INFO] 2 workers
2016-06-07 20:12:10 [3961] [INFO] Handling signal: int
2016-06-07 20:12:10 [3961] [INFO] Shutting down: Master
2016-06-07 20:12:44 [4053] [INFO] Starting gunicorn 19.1.0
2016-06-07 20:12:44 [4053] [INFO] Listening at: http://127.0.0.1:8000 (4053)
2016-06-07 20:12:44 [4053] [INFO] Using worker: egg:meinheld#gunicorn_worker
2016-06-07 20:12:44 [4060] [INFO] Booting worker with pid: 4060
2016-06-07 20:12:44 [4063] [INFO] Booting worker with pid: 4063
2016-06-07 20:12:44 [4053] [INFO] 2 workers
2016-06-07 20:13:14 [4053] [INFO] 2 workers
2016-06-07 20:13:43 [4053] [INFO] 2 workers
2016-06-07 20:14:07 [4053] [INFO] 2 workers
2016-06-07 20:14:07 [4053] [INFO] Handling signal: int
2016-06-07 20:14:07 [4063] [ERROR] Exception in worker process:
Traceback (most recent call last):
  File "/home/ralbright/anaconda2/lib/python2.7/site-packages/gunicorn-19.1.0-py2.7.egg/gunicorn/arbiter.py", line 507, in spawn_worker
    worker.init_process()
  File "/home/ralbright/anaconda2/lib/python2.7/site-packages/gunicorn-19.1.0-py2.7.egg/gunicorn/workers/base.py", line 120, in init_process
    self.run()
  File "/home/ralbright/anaconda2/lib/python2.7/site-packages/meinheld/gmeinheld.py", line 44, in run
    server.run(self.wsgi)
KeyboardInterrupt
Traceback (most recent call last):
  File "/home/ralbright/anaconda2/lib/python2.7/site-packages/gunicorn-19.1.0-py2.7.egg/gunicorn/arbiter.py", line 507, in spawn_worker
    worker.init_process()
  File "/home/ralbright/anaconda2/lib/python2.7/site-packages/gunicorn-19.1.0-py2.7.egg/gunicorn/workers/base.py", line 120, in init_process
    self.run()
  File "/home/ralbright/anaconda2/lib/python2.7/site-packages/meinheld/gmeinheld.py", line 44, in run
    server.run(self.wsgi)
KeyboardInterrupt
2016-06-07 20:14:07 [4063] [INFO] Worker exiting (pid: 4063)
2016-06-07 20:14:07 [4060] [ERROR] Exception in worker process:
Traceback (most recent call last):
  File "/home/ralbright/anaconda2/lib/python2.7/site-packages/gunicorn-19.1.0-py2.7.egg/gunicorn/arbiter.py", line 507, in spawn_worker
    worker.init_process()
  File "/home/ralbright/anaconda2/lib/python2.7/site-packages/gunicorn-19.1.0-py2.7.egg/gunicorn/workers/base.py", line 120, in init_process
    self.run()
  File "/home/ralbright/anaconda2/lib/python2.7/site-packages/meinheld/gmeinheld.py", line 44, in run
    server.run(self.wsgi)
KeyboardInterrupt
Traceback (most recent call last):
  File "/home/ralbright/anaconda2/lib/python2.7/site-packages/gunicorn-19.1.0-py2.7.egg/gunicorn/arbiter.py", line 507, in spawn_worker
    worker.init_process()
  File "/home/ralbright/anaconda2/lib/python2.7/site-packages/gunicorn-19.1.0-py2.7.egg/gunicorn/workers/base.py", line 120, in init_process
    self.run()
  File "/home/ralbright/anaconda2/lib/python2.7/site-packages/meinheld/gmeinheld.py", line 44, in run
    server.run(self.wsgi)
KeyboardInterrupt
2016-06-07 20:14:07 [4060] [INFO] Worker exiting (pid: 4060)
2016-06-07 20:14:07 [4053] [INFO] Shutting down: Master
